Workbook

Sheet Summary PO Permit
A1: Summary PO RT/RW (CLUSTER NAME)
A2: Permit | B2: 7650000
A3: (Permit + PPh 2.65%) | B3: =B2+(B2*2.65%) -> 7852725

Sheet BoQ NRO Cluster
A1: DISTRIBUSI - SUBFEEEDER | N1: AS PLAN
A2: BOQ GPON FTTH FOR OPTICAL DISTRIBUTION NETWORK (ODN) | N2: OLT Name
A3: PT. EKA MAS REPUBLIK ODN, OSP, Aktivasi, Instalasi, Integrasi, Testing & Dokumentasi | N3: Cluster | S3: VENDOR CODE
A4: PROJECT ROLL OUT 2026 | N4: Net Type | S4: VENDOR NAME
N5: HP | S5: VENDOR STATUS | T5: TURNKEY
A6: No | B6: Description/Item | C6: Unit | D6: Material Qty | E6: Service Qty | F6: Material Price | G6: Service Price | H6: Total Material Price | I6: Total Service Price | J6: Total Price | M6: Koreksi No Material | N6: No Material | O6: Short Text/Description SAP | P6: Remarks | Q6: Service
A7: 1 | B7: Pengamanan & Persiapan
A8: 1.1 | B8: Pengamanan Perizinan dan K3 | C8: ls | E8: 1 | L8: =F8+G8 -> 0 | N8: 500004774 | O8: PENGAMANAN PERIZINAN DAN K3 (Cluster Only) | P8: Material | Q8: Vendor
A9: 1.2 | B9: Transportasi, Mobilisasi & demobilisasi | C9: ls | E9: 1 | H9: =D9*F9 -> 0 | K9: =D9+E9 -> 1 | L9: =F9+G9 -> 0 | N9: 500003890 | O9: TRANSPORTASI, MOBILISASI DAN DEMOBILISASI | P9: Material | Q9: Vendor
A10: Sub Total Preparation | H10: =SUM(H8:H8) -> 0 | I10: =SUM(I8:I8) -> 0 | J10: =H10+I10 -> 0
A12: 2 | B12: ODN, OSP, Aktivasi, Instalasi, termasuk ATP Civil Work, Integrasi, Testing & Dokumentasi
A13: 2.1 | B13: ODN
A14: A | B14: FO core type SM G.652.D-ADSS (Aerial dan Underground)
B15: FO core type SM G.652.D-ADSS 24 cores | C15: meter | D15: =--(IF(T$5="TURNKEY",E16)) -> 0 | H15: =D15*F15 -> 0 | I15: =E15*G15 -> 0 | K15: =D15+E15 -> 0 | L15: =F15+G15 -> 0 | N15: 200000100 | O15: FO TYPE SM G.652.D-ADSS 24 CORES | P15: Material | Q15: Internal
B16: Instal FO core type SM G.652.D-ADSS 24 cores | C16: meter | E16: =SUM('BoM CLUSTER UG'!C24:L27) -> 0 | H16: =D16*F16 -> 0 | I16: =E16*G16 -> 0 | K16: =D16+E16 -> 0 | L16: =F16+G16 -> 0 | N16: 500002050 | O16: INSTAL FO TYPE SM G.652.D-ADSS 24 CORES | P16: Service | Q16: Vendor
B17: FO core type SM G.652.D-ADSS 36 cores | C17: meter | D17: =--(IF(T$5="TURNKEY",E18)) -> 0 | H17: =D17*F17 -> 0 | I17: =E17*G17 -> 0 | K17: =D17+E17 -> 0 | L17: =F17+G17 -> 0 | N17: 200000975 | O17: FO TYPE SM G.652.D-ADSS 36 CORES | P17: Material | Q17: Internal
B18: Instal FO core type SM G.652.D-ADSS 36 cores | C18: meter | E18: =SUM('BoM CLUSTER UG'!C28:L31) -> 0 | H18: =D18*F18 -> 0 | I18: =E18*G18 -> 0 | K18: =D18+E18 -> 0 | L18: =F18+G18 -> 0 | N18: 500002051 | O18: INSTAL FO TYPE SM G.652.D-ADSS 36 CORES | P18: Service | Q18: Vendor
B19: FO core type SM G.652.D-ADSS 48 cores | C19: meter | D19: =--(IF(T$5="TURNKEY",E20)) -> 0 | H19: =D19*F19 -> 0 | I19: =E19*G19 -> 0 | K19: =D19+E19 -> 0 | L19: =F19+G19 -> 0 | N19: 200001038 | O19: FO TYPE SM G.652.D-ADSS 48 CORES | P19: Material | Q19: Internal
B20: Instal FO core type SM G.652.D-ADSS 48 cores | C20: meter | E20: =SUM('BoM CLUSTER UG'!C32:L35) -> 0 | H20: =D20*F20 -> 0 | I20: =E20*G20 -> 0 | K20: =D20+E20 -> 0 | L20: =F20+G20 -> 0 | N20: 500002052 | O20: INSTAL FO TYPE SM G.652.D-ADSS 48 CORES | P20: Service | Q20: Vendor
B21: FO core type SM G.652.D-ADSS 72 cores | C21: meter | N21: 200001970 | O21: FO TYPE SM G.652.D-ADSS 72 CORES | P21: Material | Q21: Internal
B22: Instal FO core type SM G.652.D-ADSS 72 cores | C22: meter | N22: 500003410 | O22: INSTAL FO TYPE SM G.652.D-ADSS 72 CORES | P22: Service | Q22: Vendor
B23: FO core type SM G.652.D-ADSS 96 cores | C23: meter | N23: 200001630 | O23: FO TYPE SM G.652.D-ADSS 96 CORES | P23: Material | Q23: Internal
B24: Instal FO core type SM G.652.D-ADSS 96 cores | C24: meter | N24: 500002890 | O24: INSTAL FO TYPE SM G.652.D-ADSS 96 CORES | P24: Service | Q24: Vendor
B25: FO core type SM G.652.D-ADSS 144 cores | C25: meter | H25: =D25*F25 -> 0 | I25: =E25*G25 -> 0 | K25: =D25+E25 -> 0 | L25: =F25+G25 -> 0 | N25: 200001030 | O25: FO TYPE SM G.652.D-ADSS 144 CORES | P25: Material | Q25: Internal
B26: Instal FO core type SM G.652.D-ADSS 144 cores | C26: meter | H26: =D26*F26 -> 0 | I26: =E26*G26 -> 0 | K26: =D26+E26 -> 0 | L26: =F26+G26 -> 0 | N26: 500002088 | O26: INSTAL FO TYPE SM G.652.D-ADSS 144 CORES | P26: Service | Q26: Vendor
B27: FO core type SM G.652.D-ADSS 288 cores | C27: meter | H27: =D27*F27 -> 0 | I27: =E27*G27 -> 0 | K27: =D27+E27 -> 0 | L27: =F27+G27 -> 0 | N27: 200001015 | O27: FO TYPE SM G.652.D-ADSS 288 CORES | P27: Material | Q27: Internal
B28: Instal FO core type SM G.652.D-ADSS 288 cores | C28: meter | H28: =D28*F28 -> 0 | I28: =E28*G28 -> 0 | K28: =D28+E28 -> 0 | L28: =F28+G28 -> 0 | N28: 500002089 | O28: INSTAL FO TYPE SM G.652.D-ADSS 288 CORES | P28: Service | Q28: Vendor
B29: Round Cable 1C - 50 m | C29: set | D29: =--(IF(T$5="TURNKEY",E30)) -> 0 | N29: 200002668 | O29: ROUND CABLE 1C - 50 M | P29: Material
B30: Install Round Cable 1C - 50 m | C30: set | E30: =SUM('BoM CLUSTER UG'!C17:L17) -> 0 | N30: 500004722 | O30: INSTALL ROUND CABLE 1C - 50 M | P30: Service
B31: Round Cable 1C - 100 m | C31: set | D31: =--(IF(T$5="TURNKEY",E32)) -> 0 | N31: 200002669 | O31: ROUND CABLE 1C - 100 M | P31: Material
B32: Install Round Cable 1C - 100 m | C32: set | E32: =SUM('BoM CLUSTER UG'!C18:L18) -> 0 | N32: 500004723 | O32: INSTALL ROUND CABLE 1C - 100 M | P32: Service
B33: Round Cable 1C - 150 m | C33: set | D33: =--(IF(T$5="TURNKEY",E34)) -> 0 | N33: 200002670 | O33: ROUND CABLE 1C - 150 M | P33: Material
B34: Install Round Cable 1C - 150 m | C34: set | E34: =SUM('BoM CLUSTER UG'!C19:L19) -> 0 | N34: 500004724 | O34: INSTALL ROUND CABLE 1C - 150 M | P34: Service
B35: Round Cable 1C - 200 m | C35: set | D35: =--(IF(T$5="TURNKEY",E36)) -> 0 | N35: 200002671 | O35: ROUND CABLE 1C - 200 M | P35: Material
B36: Install Round Cable 1C - 200 m | C36: set | E36: =SUM('BoM CLUSTER UG'!C20:L20) -> 0 | N36: 500004725 | O36: INSTALL ROUND CABLE 1C - 200 M | P36: Service
B37: Round Cable 1C - 250 m | C37: set | D37: =--(IF(T$5="TURNKEY",E38)) -> 0 | N37: 200002713 | O37: ROUND CABLE 1C - 250 M | P37: Material
B38: Install Round Cable 1C - 250 m | C38: set | E38: =SUM('BoM CLUSTER UG'!C21:L21) -> 0 | N38: 500004777 | O38: INSTALL ROUND CABLE 1C - 250 M | P38: Service
B39: Round Cable 1C - 300 m | C39: set | D39: =--(IF(T$5="TURNKEY",E40)) -> 0 | N39: 200002714 | O39: ROUND CABLE 1C - 300 M | P39: Material
B40: Install Round Cable 1C - 300 m | C40: set | E40: =SUM('BoM CLUSTER UG'!C22:L22) -> 0 | N40: 500004778 | O40: INSTALL ROUND CABLE 1C - 300 M | P40: Service
A41: B | B41: Fiber Distribution Terminal (FDT) SC/APC c/w Box, matrix terminal, Patchtray, Pigtail, label & accessories include concrete base | H41: =D41*F41 -> 0 | I41: =E41*G41 -> 0 | K41: =D41+E41 -> 0 | L41: =F41+G41 -> 0
...

Sheet BoM CLUSTER UG
A1: BoM Cluster - Standard ODN | B1: ='BoQ NRO Cluster'!O3 -> 0 | C1: FDT 1 | D1: FDT 2 | E1: FDT 3 | F1: FDT 4 | G1: FDT 5 | H1: FDT 6 | I1: FDT 7 | J1: FDT 8 | K1: FDT 9 | L1: FDT 10 | M1: Unit | N1: Remarks
A2: Total Rute | B2: Line A - 24C/2T | C2: 0 | D2: 0 | E2: 0 | F2: 0 | G2: 0 | H2: 0 | I2: 0 | J2: 0 | K2: 0 | L2: 0 | M2: m | N2: qty based on design
B3: Line B - 24C/2T | C3: 0 | D3: 0 | E3: 0 | F3: 0 | G3: 0 | H3: 0 | I3: 0 | J3: 0 | K3: 0 | L3: 0 | M3: m | N3: qty based on design
B4: Line C - 24C/2T | C4: 0 | D4: 0 | E4: 0 | F4: 0 | G4: 0 | H4: 0 | I4: 0 | J4: 0 | K4: 0 | L4: 0 | M4: m | N4: qty based on design
B5: Line D - 24C/2T | C5: 0 | D5: 0 | E5: 0 | F5: 0 | G5: 0 | H5: 0 | I5: 0 | J5: 0 | K5: 0 | L5: 0 | M5: m | N5: qty based on design
B6: Line A - 36C/3T | C6: 0 | D6: 0 | E6: 0 | F6: 0 | G6: 0 | H6: 0 | I6: 0 | J6: 0 | K6: 0 | L6: 0 | M6: m | N6: qty based on design
B7: Line B - 36C/3T | C7: 0 | D7: 0 | E7: 0 | F7: 0 | G7: 0 | H7: 0 | I7: 0 | J7: 0 | K7: 0 | L7: 0 | M7: m | N7: qty based on design
B8: Line C - 36C/3T | C8: 0 | D8: 0 | E8: 0 | F8: 0 | G8: 0 | H8: 0 | I8: 0 | J8: 0 | K8: 0 | L8: 0 | M8: m | N8: qty based on design
B9: Line D - 36C/3T | C9: 0 | D9: 0 | E9: 0 | F9: 0 | G9: 0 | H9: 0 | I9: 0 | J9: 0 | K9: 0 | L9: 0 | M9: m | N9: qty based on design
B10: Line A - 48C/4T | C10: 0 | D10: 0 | E10: 0 | F10: 0 | G10: 0 | H10: 0 | I10: 0 | J10: 0 | K10: 0 | L10: 0 | M10: m | N10: qty based on design
B11: Line B - 48C/4T | C11: 0 | D11: 0 | E11: 0 | F11: 0 | G11: 0 | H11: 0 | I11: 0 | J11: 0 | K11: 0 | L11: 0 | M11: m | N11: qty based on design
B12: Line C - 48C/4T | C12: 0 | D12: 0 | E12: 0 | F12: 0 | G12: 0 | H12: 0 | I12: 0 | J12: 0 | K12: 0 | L12: 0 | M12: m | N12: qty based on design
B13: Line D - 48C/4T | C13: 0 | D13: 0 | E13: 0 | F13: 0 | G13: 0 | H13: 0 | I13: 0 | J13: 0 | K13: 0 | L13: 0 | M13: m | N13: qty based on design
A14: Total Rute | C14: =SUM(C2:C13) -> 0 | D14: =SUM(D2:D13) -> 0 | E14: =SUM(E2:E13) -> 0 | F14: =SUM(F2:F13) -> 0 | G14: =SUM(G2:G13) -> 0 | H14: =SUM(H2:H13) -> 0 | I14: =SUM(I2:I13) -> 0 | J14: =SUM(J2:J13) -> 0 | ... L14: =SUM(L2:L13) -> 0 | M14: m | N14: auto (based on formula)
B15: Rute Strand Wire | C15: 0 | D15: 0 | E15: 0 | F15: 0 | G15: 0 | H15: 0 | I15: 0 | J15: 0 | K15: 0 | L15: 0 | M15: m | N15: qty based on design
A16: BoM Cluster - Low Cost ODN | B16: ='BoQ NRO Cluster'!O3 -> 0 | C16: HUB BOX 1 | D16: HUB BOX 2 | E16: HUB BOX 3 | F16: HUB BOX 4 | G16: HUB BOX 5 | H16: HUB BOX 6 | I16: HUB BOX 7 | J16: HUB BOX 8 | K16: HUB BOX 9 | L16: HUB BOX 10 | M16: Unit | N16: Remarks
A17: Total Rute | B17: Round Cable 1C - 50 m | C17: 0 | D17: 0 | E17: 0 | F17: 0 | G17: 0 | H17: 0 | I17: 0 | J17: 0 | K17: 0 | L17: 0 | M17: m | N17: qty based on design
B18: Round Cable 1C - 100 m | C18: 0 | D18: 0 | E18: 0 | F18: 0 | G18: 0 | H18: 0 | I18: 0 | J18: 0 | K18: 0 | L18: 0 | M18: m | N18: qty based on design
B19: Round Cable 1C - 150 m | C19: 0 | D19: 0 | E19: 0 | F19: 0 | G19: 0 | H19: 0 | I19: 0 | J19: 0 | K19: 0 | L19: 0 | M19: m | N19: qty based on design
B20: Round Cable 1C - 200 m | C20: 0 | D20: 0 | E20: 0 | F20: 0 | G20: 0 | H20: 0 | I20: 0 | J20: 0 | K20: 0 | L20: 0 | M20: m | N20: qty based on design
B21: Round Cable 1C - 250 m | C21: 0 | D21: 0 | E21: 0 | F21: 0 | G21: 0 | H21: 0 | I21: 0 | J21: 0 | K21: 0 | L21: 0 | M21: m | N21: qty based on design
B22: Round Cable 1C - 300 m | C22: 0 | D22: 0 | E22: 0 | F22: 0 | G22: 0 | H22: 0 | I22: 0 | J22: 0 | K22: 0 | L22: 0 | M22: m | N22: qty based on design
A23: Total Rute | C23: =SUM(C17:C22) -> 0 | D23: =SUM(D17:D22) -> 0 | E23: =SUM(E17:E22) -> 0 | F23: =SUM(F17:F22) -> 0 | G23: =SUM(G17:G22) -> 0 | H23: =SUM(H17:H22) -> 0 | I23: =SUM(I17:I22) -> 0 | J23: =SUM(J17:J22) -> 0 | ... L23: =SUM(L17:L22) -> 0 | M23: m | N23: auto (based on formula)
A24: Total Panjang Kabel (Slack + Toleransi 5%) | B24: =B2 -> Line A - 24C/2T | C24: =IF(C2=0,0,(ROUNDUP(((C2)+(C$61+C$53)*20)*1.05,0))) -> 0 | D24: =IF(D2=0,0,(ROUNDUP(((D2)+(D$61+D$53)*20)*1.05,0))) -> 0 | E24: =IF(E2=0,0,(ROUNDUP(((E2)+(E$61+E$53)*20)*1.05,0))) -> 0 | F24: =IF(F2=0,0,(ROUNDUP(((F2)+(F$61+F$53)*20)*1.05,0))) -> 0 | G24: =IF(G2=0,0,(ROUNDUP(((G2)+(G$61+G$53)*20)*1.05,0))) -> 0 | H24: =IF(H2=0,0,(ROUNDUP(((H2)+(H$61+H$53)*20)*1.05,0))) -> 0 | I24: =IF(I2=0,0,(ROUNDUP(((I2)+(I$61+I$53)*20)*1.05,0))) -> 0 | J24: =IF(J2=0,0,(ROUNDUP(((J2)+(J$61+J$53)*20)*1.05,0))) -> 0 | ... L24: =IF(L2=0,0,(ROUNDUP(((L2)+(L$61+L$53)*20)*1.05,0))) -> 0 | M24: m | N24: auto (based on formula)
B25: =B3 -> Line B - 24C/2T | C25: =IF(C3=0,0,(ROUNDUP(((C3)+(C$62+C$54)*20)*1.05,0))) -> 0 | D25: =IF(D3=0,0,(ROUNDUP(((D3)+(D$62+D$54)*20)*1.05,0))) -> 0 | E25: =IF(E3=0,0,(ROUNDUP(((E3)+(E$62+E$54)*20)*1.05,0))) -> 0 | F25: =IF(F3=0,0,(ROUNDUP(((F3)+(F$62+F$54)*20)*1.05,0))) -> 0 | G25: =IF(G3=0,0,(ROUNDUP(((G3)+(G$62+G$54)*20)*1.05,0))) -> 0 | H25: =IF(H3=0,0,(ROUNDUP(((H3)+(H$62+H$54)*20)*1.05,0))) -> 0 | I25: =IF(I3=0,0,(ROUNDUP(((I3)+(I$62+I$54)*20)*1.05,0))) -> 0 | J25: =IF(J3=0,0,(ROUNDUP(((J3)+(J$62+J$54)*20)*1.05,0))) -> 0 | ... L25: =IF(L3=0,0,(ROUNDUP(((L3)+(L$62+L$54)*20)*1.05,0))) -> 0 | M25: m | N25: auto (based on formula)
B26: =B4 -> Line C - 24C/2T | C26: =IF(C4=0,0,(ROUNDUP(((C4)+(C$63+C$55)*20)*1.05,0))) -> 0 | D26: =IF(D4=0,0,(ROUNDUP(((D4)+(D$63+D$55)*20)*1.05,0))) -> 0 | E26: =IF(E4=0,0,(ROUNDUP(((E4)+(E$63+E$55)*20)*1.05,0))) -> 0 | F26: =IF(F4=0,0,(ROUNDUP(((F4)+(F$63+F$55)*20)*1.05,0))) -> 0 | G26: =IF(G4=0,0,(ROUNDUP(((G4)+(G$63+G$55)*20)*1.05,0))) -> 0 | H26: =IF(H4=0,0,(ROUNDUP(((H4)+(H$63+H$55)*20)*1.05,0))) -> 0 | I26: =IF(I4=0,0,(ROUNDUP(((I4)+(I$63+I$55)*20)*1.05,0))) -> 0 | J26: =IF(J4=0,0,(ROUNDUP(((J4)+(J$63+J$55)*20)*1.05,0))) -> 0 | ... L26: =IF(L4=0,0,(ROUNDUP(((L4)+(L$63+L$55)*20)*1.05,0))) -> 0 | M26: m | N26: auto (based on formula)
B27: =B5 -> Line D - 24C/2T | C27: =IF(C5=0,0,(ROUNDUP(((C5)+(C$64+C$56)*20)*1.05,0))) -> 0 | D27: =IF(D5=0,0,(ROUNDUP(((D5)+(D$64+D$56)*20)*1.05,0))) -> 0 | E27: =IF(E5=0,0,(ROUNDUP(((E5)+(E$64+E$56)*20)*1.05,0))) -> 0 | F27: =IF(F5=0,0,(ROUNDUP(((F5)+(F$64+F$56)*20)*1.05,0))) -> 0 | G27: =IF(G5=0,0,(ROUNDUP(((G5)+(G$64+G$56)*20)*1.05,0))) -> 0 | H27: =IF(H5=0,0,(ROUNDUP(((H5)+(H$64+H$56)*20)*1.05,0))) -> 0 | I27: =IF(I5=0,0,(ROUNDUP(((I5)+(I$64+I$56)*20)*1.05,0))) -> 0 | J27: =IF(J5=0,0,(ROUNDUP(((J5)+(J$64+J$56)*20)*1.05,0))) -> 0 | ... L27: =IF(L5=0,0,(ROUNDUP(((L5)+(L$64+L$56)*20)*1.05,0))) -> 0 | M27: m | N27: auto (based on formula)
B28: =B6 -> Line A - 36C/3T | C28: =IF(C6=0,0,(ROUNDUP(((C6)+(C$61+C$53)*20)*1.05,0))) -> 0 | D28: =IF(D6=0,0,(ROUNDUP(((D6)+(D$61+D$53)*20)*1.05,0))) -> 0 | E28: =IF(E6=0,0,(ROUNDUP(((E6)+(E$61+E$53)*20)*1.05,0))) -> 0 | F28: =IF(F6=0,0,(ROUNDUP(((F6)+(F$61+F$53)*20)*1.05,0))) -> 0 | G28: =IF(G6=0,0,(ROUNDUP(((G6)+(G$61+G$53)*20)*1.05,0))) -> 0 | H28: =IF(H6=0,0,(ROUNDUP(((H6)+(H$61+H$53)*20)*1.05,0))) -> 0 | I28: =IF(I6=0,0,(ROUNDUP(((I6)+(I$61+I$53)*20)*1.05,0))) -> 0 | J28: =IF(J6=0,0,(ROUNDUP(((J6)+(J$61+J$53)*20)*1.05,0))) -> 0 | ... L28: =IF(L6=0,0,(ROUNDUP(((L6)+(L$61+L$53)*20)*1.05,0))) -> 0 | M28: m | N28: auto (based on formula)
B29: =B7 -> Line B - 36C/3T | C29: =IF(C7=0,0,(ROUNDUP(((C7)+(C$62+C$54)*20)*1.05,0))) -> 0 | D29: =IF(D7=0,0,(ROUNDUP(((D7)+(D$62+D$54)*20)*1.05,0))) -> 0 | E29: =IF(E7=0,0,(ROUNDUP(((E7)+(E$62+E$54)*20)*1.05,0))) -> 0 | F29: =IF(F7=0,0,(ROUNDUP(((F7)+(F$62+F$54)*20)*1.05,0))) -> 0 | G29: =IF(G7=0,0,(ROUNDUP(((G7)+(G$62+G$54)*20)*1.05,0))) -> 0 | H29: =IF(H7=0,0,(ROUNDUP(((H7)+(H$62+H$54)*20)*1.05,0))) -> 0 | I29: =IF(I7=0,0,(ROUNDUP(((I7)+(I$62+I$54)*20)*1.05,0))) -> 0 | J29: =IF(J7=0,0,(ROUNDUP(((J7)+(J$62+J$54)*20)*1.05,0))) -> 0 | ... L29: =IF(L7=0,0,(ROUNDUP(((L7)+(L$62+L$54)*20)*1.05,0))) -> 0 | M29: m | N29: auto (based on formula)
B30: =B8 -> Line C - 36C/3T | C30: =IF(C8=0,0,(ROUNDUP(((C8)+(C$63+C$55)*20)*1.05,0))) -> 0 | D30: =IF(D8=0,0,(ROUNDUP(((D8)+(D$63+D$55)*20)*1.05,0))) -> 0 | E30: =IF(E8=0,0,(ROUNDUP(((E8)+(E$63+E$55)*20)*1.05,0))) -> 0 | F30: =IF(F8=0,0,(ROUNDUP(((F8)+(F$63+F$55)*20)*1.05,0))) -> 0 | G30: =IF(G8=0,0,(ROUNDUP(((G8)+(G$63+G$55)*20)*1.05,0))) -> 0 | H30: =IF(H8=0,0,(ROUNDUP(((H8)+(H$63+H$55)*20)*1.05,0))) -> 0 | I30: =IF(I8=0,0,(ROUNDUP(((I8)+(I$63+I$55)*20)*1.05,0))) -> 0 | J30: =IF(J8=0,0,(ROUNDUP(((J8)+(J$63+J$55)*20)*1.05,0))) -> 0 | ... L30: =IF(L8=0,0,(ROUNDUP(((L8)+(L$63+L$55)*20)*1.05,0))) -> 0 | M30: m | N30: auto (based on formula)
B31: =B9 -> Line D - 36C/3T | C31: =IF(C9=0,0,(ROUNDUP(((C9)+(C$64+C$56)*20)*1.05,0))) -> 0 | D31: =IF(D9=0,0,(ROUNDUP(((D9)+(D$64+D$56)*20)*1.05,0))) -> 0 | E31: =IF(E9=0,0,(ROUNDUP(((E9)+(E$64+E$56)*20)*1.05,0))) -> 0 | F31: =IF(F9=0,0,(ROUNDUP(((F9)+(F$64+F$56)*20)*1.05,0))) -> 0 | G31: =IF(G9=0,0,(ROUNDUP(((G9)+(G$64+G$56)*20)*1.05,0))) -> 0 | H31: =IF(H9=0,0,(ROUNDUP(((H9)+(H$64+H$56)*20)*1.05,0))) -> 0 | I31: =IF(I9=0,0,(ROUNDUP(((I9)+(I$64+I$56)*20)*1.05,0))) -> 0 | J31: =IF(J9=0,0,(ROUNDUP(((J9)+(J$64+J$56)*20)*1.05,0))) -> 0 | ... L31: =IF(L9=0,0,(ROUNDUP(((L9)+(L$64+L$56)*20)*1.05,0))) -> 0 | M31: m | N31: auto (based on formula)
B32: =B10 -> Line A - 48C/4T | C32: =IF(C10=0,0,(ROUNDUP(((C10)+(C$61+C$53)*20)*1.05,0))) -> 0 | D32: =IF(D10=0,0,(ROUNDUP(((D10)+(D$61+D$53)*20)*1.05,0))) -> 0 | E32: =IF(E10=0,0,(ROUNDUP(((E10)+(E$61+E$53)*20)*1.05,0))) -> 0 | F32: =IF(F10=0,0,(ROUNDUP(((F10)+(F$61+F$53)*20)*1.05,0))) -> 0 | G32: =IF(G10=0,0,(ROUNDUP(((G10)+(G$61+G$53)*20)*1.05,0))) -> 0 | H32: =IF(H10=0,0,(ROUNDUP(((H10)+(H$61+H$53)*20)*1.05,0))) -> 0 | I32: =IF(I10=0,0,(ROUNDUP(((I10)+(I$61+I$53)*20)*1.05,0))) -> 0 | J32: =IF(J10=0,0,(ROUNDUP(((J10)+(J$61+J$53)*20)*1.05,0))) -> 0 | ... L32: =IF(L10=0,0,(ROUNDUP(((L10)+(L$61+L$53)*20)*1.05,0))) -> 0 | M32: m | N32: auto (based on formula)
B33: =B11 -> Line B - 48C/4T | C33: =IF(C11=0,0,(ROUNDUP(((C11)+(C$62+C$54)*20)*1.05,0))) -> 0 | D33: =IF(D11=0,0,(ROUNDUP(((D11)+(D$62+D$54)*20)*1.05,0))) -> 0 | E33: =IF(E11=0,0,(ROUNDUP(((E11)+(E$62+E$54)*20)*1.05,0))) -> 0 | F33: =IF(F11=0,0,(ROUNDUP(((F11)+(F$62+F$54)*20)*1.05,0))) -> 0 | G33: =IF(G11=0,0,(ROUNDUP(((G11)+(G$62+G$54)*20)*1.05,0))) -> 0 | H33: =IF(H11=0,0,(ROUNDUP(((H11)+(H$62+H$54)*20)*1.05,0))) -> 0 | I33: =IF(I11=0,0,(ROUNDUP(((I11)+(I$62+I$54)*20)*1.05,0))) -> 0 | J33: =IF(J11=0,0,(ROUNDUP(((J11)+(J$62+J$54)*20)*1.05,0))) -> 0 | ... L33: =IF(L11=0,0,(ROUNDUP(((L11)+(L$62+L$54)*20)*1.05,0))) -> 0 | M33: m | N33: auto (based on formula)
B34: =B12 -> Line C - 48C/4T | C34: =IF(C12=0,0,(ROUNDUP(((C12)+(C$63+C$55)*20)*1.05,0))) -> 0 | D34: =IF(D12=0,0,(ROUNDUP(((D12)+(D$63+D$55)*20)*1.05,0))) -> 0 | E34: =IF(E12=0,0,(ROUNDUP(((E12)+(E$63+E$55)*20)*1.05,0))) -> 0 | F34: =IF(F12=0,0,(ROUNDUP(((F12)+(F$63+F$55)*20)*1.05,0))) -> 0 | G34: =IF(G12=0,0,(ROUNDUP(((G12)+(G$63+G$55)*20)*1.05,0))) -> 0 | H34: =IF(H12=0,0,(ROUNDUP(((H12)+(H$63+H$55)*20)*1.05,0))) -> 0 | I34: =IF(I12=0,0,(ROUNDUP(((I12)+(I$63+I$55)*20)*1.05,0))) -> 0 | J34: =IF(J12=0,0,(ROUNDUP(((J12)+(J$63+J$55)*20)*1.05,0))) -> 0 | ... L34: =IF(L12=0,0,(ROUNDUP(((L12)+(L$63+L$55)*20)*1.05,0))) -> 0 | M34: m | N34: auto (based on formula)
B35: =B13 -> Line D - 48C/4T | C35: =IF(C13=0,0,(ROUNDUP(((C13)+(C$64+C$56)*20)*1.05,0))) -> 0 | D35: =IF(D13=0,0,(ROUNDUP(((D13)+(D$64+D$56)*20)*1.05,0))) -> 0 | E35: =IF(E13=0,0,(ROUNDUP(((E13)+(E$64+E$56)*20)*1.05,0))) -> 0 | F35: =IF(F13=0,0,(ROUNDUP(((F13)+(F$64+F$56)*20)*1.05,0))) -> 0 | G35: =IF(G13=0,0,(ROUNDUP(((G13)+(G$64+G$56)*20)*1.05,0))) -> 0 | H35: =IF(H13=0,0,(ROUNDUP(((H13)+(H$64+H$56)*20)*1.05,0))) -> 0 | I35: =IF(I13=0,0,(ROUNDUP(((I13)+(I$64+I$56)*20)*1.05,0))) -> 0 | J35: =IF(J13=0,0,(ROUNDUP(((J13)+(J$64+J$56)*20)*1.05,0))) -> 0 | ... L35: =IF(L13=0,0,(ROUNDUP(((L13)+(L$64+L$56)*20)*1.05,0))) -> 0 | M35: m | N35: auto (based on formula)
A36: Total Panjang Cable | C36: =SUM(C24:C35) -> 0 | D36: =SUM(D24:D35) -> 0 | E36: =SUM(E24:E35) -> 0 | F36: =SUM(F24:F35) -> 0 | G36: =SUM(G24:G35) -> 0 | H36: =SUM(H24:H35) -> 0 | I36: =SUM(I24:I35) -> 0 | J36: =SUM(J24:J35) -> 0 | ... L36: =SUM(L24:L35) -> 0 | M36: m | N36: auto (based on formula)
B37: Panjang Strand Wire + toleransi 5% | C37: =ROUNDUP(((C15*5%)+C15),0) -> 0 | D37: =ROUNDUP(((D15*5%)+D15),0) -> 0 | E37: =ROUNDUP(((E15*5%)+E15),0) -> 0 | F37: =ROUNDUP(((F15*5%)+F15),0) -> 0 | G37: =ROUNDUP(((G15*5%)+G15),0) -> 0 | H37: =ROUNDUP(((H15*5%)+H15),0) -> 0 | I37: =ROUNDUP(((I15*5%)+I15),0) -> 0 | J37: =ROUNDUP(((J15*5%)+J15),0) -> 0 | ... L37: =ROUNDUP(((L15*5%)+L15),0) -> 0 | M37: m | N37: auto (based on formula)
A38: Total FDT Pole Mounted | B38: FDT Pole Mounted 48 core | C38: 0 | D38: 0 | E38: 0 | F38: 0 | G38: 0 | H38: 0 | I38: 0 | J38: 0 | K38: 0 | L38: 0 | M38: set | N38: qty based on design
B39: FDT Pole Mounted 72 core | C39: 0 | D39: 0 | E39: 0 | F39: 0 | G39: 0 | H39: 0 | I39: 0 | J39: 0 | K39: 0 | L39: 0 | M39: set | N39: qty based on design
B40: FDT Pole Mounted 96 core | C40: 0 | D40: 0 | E40: 0 | F40: 0 | G40: 0 | H40: 0 | I40: 0 | J40: 0 | K40: 0 | L40: 0 | M40: set | N40: qty based on design
...
